# ********RoostGPT********
"""
Test generated by RoostGPT for test turbo-pytest using AI Type Open AI and AI Model gpt-4-1106-preview

ROOST_METHOD_HASH=biling_system_Bill_App_exit_app_ed9c77b22d
ROOST_METHOD_SIG_HASH=biling_system_Bill_App_exit_app_a10beac2f8

================================VULNERABILITIES================================
Vulnerability: CWE-749: Exposed Dangerous Method or Function
Issue: The exit_app method allows the application to be terminated by external sources which might be exploited if wrapped in unsanitized user-defined callbacks.
Solution: Ensure that the exit_app method cannot be invoked by unauthorized users or through unsanitized callbacks. Implement proper authentication and authorization checks before allowing the application to exit.

Vulnerability: CWE-272: Least Privilege Violation
Issue: The code does not demonstrate any privilege level checks which might lead to unauthorized access to application functionalities.
Solution: Implement user role management and check user privileges before allowing access to sensitive functionalities within the application.

Vulnerability: CWE-598: Use of GET Request Method With Sensitive Query Strings
Issue: While not directly visible in the provided code snippet, the use of tkinter and message boxes can potentially lead to the exposure of sensitive information if used in conjunction with networked GET requests.
Solution: Avoid using GET requests for transmitting sensitive data. If this code is part of a networked application, ensure POST requests are used and data is encrypted during transmission.

Vulnerability: CWE-117: Improper Output Neutralization for Logs
Issue: The code does not include any logging, which is a common oversight that can lead to missing traces of unauthorized access or other malicious activities.
Solution: Implement comprehensive logging throughout the application, ensuring that log entries are properly sanitized to prevent log injection attacks.

Vulnerability: CWE-215: Information Exposure Through Debug Information
Issue: If exceptions are not handled properly throughout the application, it could lead to exposure of stack traces or other sensitive information in a production environment.
Solution: Use proper exception handling to catch and manage exceptions, ensuring that sensitive information is not exposed in error messages or logs.

================================================================================
Scenario 1: User confirms exit
Details:
  TestName: test_exit_app_confirmation
  Description: This test verifies that when the user confirms the exit prompt, the application closes.
Execution:
  Arrange: Mock the messagebox.askyesno to return True, simulating a user clicking "Yes" to confirm the exit.
  Act: Call the exit_app method.
  Assert: Check that self.root.destroy has been called.
Validation:
  Rationalizing the importance of this test ensures that the application exits when the user intends to leave, adhering to the expected behavior of the exit prompt.

Scenario 2: User cancels exit
Details:
  TestName: test_exit_app_cancellation
  Description: This test checks if the application remains open when the user cancels the exit prompt.
Execution:
  Arrange: Mock the messagebox.askyesno to return False, simulating a user clicking "No" to cancel the exit.
  Act: Call the exit_app method.
  Assert: Verify that self.root.destroy has not been called.
Validation:
  This test is crucial to ensure that the application does not close if the user decides not to exit, thus respecting the user's decision and the application's expected behavior.

Scenario 3: Exit prompt closed with the window manager (e.g., clicking 'X' on the prompt)
Details:
  TestName: test_exit_app_prompt_closed
  Description: This test ensures that the application does not close if the exit prompt is closed using the window manager without making a choice.
Execution:
  Arrange: Mock the messagebox.askyesno to simulate a None return value, as if the prompt was closed without a choice.
  Act: Call the exit_app method.
  Assert: Verify that self.root.destroy has not been called.
Validation:
  This test validates that the application handles the edge case where the exit prompt is closed without user input, ensuring that the application remains open, which is in line with the user's potential expectation of not having made a decision.

Scenario 4: MessageBox exception handling
Details:
  TestName: test_exit_app_messagebox_exception
  Description: This test ensures that the application handles any exceptions thrown by the messagebox.askyesno method gracefully.
Execution:
  Arrange: Mock the messagebox.askyesno to raise an exception, such as a RuntimeError.
  Act: Call the exit_app method within a try-except block to handle the potential exception.
  Assert: Verify that an exception is caught and that the application does not crash.
Validation:
  Testing exception handling is important to ensure the robustness of the application. It should not crash under unexpected conditions, but rather handle them gracefully, maintaining a good user experience.
"""

# ********RoostGPT********
from biling_system import Bill_App
import pytest
from unittest.mock import patch, Mock
from tkinter import messagebox

# Scenario 1: User confirms exit
def test_exit_app_confirmation():
    with patch.object(Bill_App, 'root', create=True) as mock_root:
        with patch.object(messagebox, 'askyesno', return_value=True) as mock_askyesno:
            app = Bill_App(mock_root)
            app.exit_app()
            mock_askyesno.assert_called_once_with("Exit", "Do you really want to exit?")
            mock_root.destroy.assert_called_once()

# Scenario 2: User cancels exit
def test_exit_app_cancellation():
    with patch.object(Bill_App, 'root', create=True) as mock_root:
        with patch.object(messagebox, 'askyesno', return_value=False) as mock_askyesno:
            app = Bill_App(mock_root)
            app.exit_app()
            mock_askyesno.assert_called_once_with("Exit", "Do you really want to exit?")
            mock_root.destroy.assert_not_called()

# Scenario 3: Exit prompt closed with the window manager
def test_exit_app_prompt_closed():
    with patch.object(Bill_App, 'root', create=True) as mock_root:
        with patch.object(messagebox, 'askyesno', return_value=None) as mock_askyesno:
            app = Bill_App(mock_root)
            app.exit_app()
            mock_askyesno.assert_called_once_with("Exit", "Do you really want to exit?")
            mock_root.destroy.assert_not_called()

# Scenario 4: MessageBox exception handling
def test_exit_app_messagebox_exception():
    with patch.object(Bill_App, 'root', create=True) as mock_root:
        with patch.object(messagebox, 'askyesno', side_effect=RuntimeError) as mock_askyesno:
            app = Bill_App(mock_root)
            try:
                app.exit_app()
                assert True  # Exception was handled
            except RuntimeError:
                pytest.fail("RuntimeError was not handled by the application")
            mock_askyesno.assert_called_once_with("Exit", "Do you really want to exit?")
            mock_root.destroy.assert_not_called()
